Workbook

Sheet Cover
B2: PLS GROUP LIMITED
B3: ASX: PLS | Spodumene concentrate | Pilgangoora, Western Australia
B5: Equity valuation model
B6: FMAA x Shared Value Project - Investing for the Future Case Competition 2026
B8: Prepared for | C8: FMAA Asset Management - Australian ASX 200 long-only fund
B9: Coverage team | C9: Shared Value Coverage
B10: Valuation date | C10: 5 September 2026
B11: Reporting currency | C11: A$ (Australian dollars), millions unless stated
B12: Fiscal year end | C12: 30 June
B14: HOW TO USE THIS MODEL
B15: 1. Assumptions!C7 holds the scenario switch. Change it to Bear / Base / Bull and the entire
B16: model - production, prices, costs, capex, statements, DCF and target price - repoints.
B17: 2. Every projected cell is a live formula. Nothing downstream of Assumptions is typed in.
B18: 3. Blue text = hardcoded input. Black = formula. Green = link to another sheet.
B19: Yellow fill = key judgement the reviewer should interrogate first.
B20: 4. Sources lists the provenance of every input, tagged A (actual) / G (guidance) /
B21: M (market) / D (derived) / E (our estimate) / C (prescribed by the case).
B23: CONTENTS
B24: Assumptions | C24: Scenario switch, market data, CAPM and WACC build, operating drivers
B25: Deck | C25: Production by asset, realised price, unit cost and capex - all three scenarios
B26: Revenue Build | C26: Volume x price bridge by asset, royalties, freight
B27: Income Statement | C27: FY24A-FY36F P&L
B28: Balance Sheet | C28: FY24A-FY36F balance sheet
B29: Cash Flow | C29: FY24A-FY36F cash flow and net working capital
B30: DCF | C30: Unlevered FCFF, WACC discounting, terminal value, equity bridge
B31: Sensitivity | C31: WACC x TGR, price x cost, price x volume data tables
B32: Scenario Summary | C32: Bear / Base / Bull outputs side by side and probability weighting
B33: SOTP NAV | C33: Risked asset-by-asset net asset value cross-check
B34: Trading Comps | C34: ASX diversified peers and global lithium pure-plays
B35: Precedents | C35: Lithium M&A precedent transaction multiples
... B40: Sources | C40: Provenance register for every input
B42: IMPORTANT
B43: Prepared as a university case-competition submission using publicly available information.
B44: Not investment advice and not a substitute for independent professional research.
B45: Forecasts are the authors' estimates and will differ from outcomes.

Sheet Assumptions
B2: Assumptions and WACC
B3: Every driver in the model resolves to a cell on this sheet | S3: Bear
B4: PLS Group Limited (ASX: PLS) | Valuation date 5 September 2026 | All figures A$ unless stated | S4: Base
S5: Bull
B6: SCENARIO SWITCH
B7: Active scenario | C7: Base | F7: Change this cell to repoint the whole model. Bear / Base / Bull.
B8: Scenario index | C8: =MATCH($C$7,$S$3:$S$5,0) -> 2 | F8: 1 = Bear, 2 = Base, 3 = Bull. Drives every CHOOSE() in the model.
B10: MARKET DATA
B11: Last close (A$/share) | C11: 5.48 | D11: M Market Index / Google Finance, early Sep-26
B12: Shares on issue (m) | C12: 3220 | D12: M stockanalysis.com
B13: Market capitalisation (A$m) | C13: =C11*C12 -> 17645.6
B14: 52-week high (A$) | C14: 6.81
B15: 52-week low (A$) | C15: 1.91
B16: Move off 52-week low | C16: =C11/C15-1 -> 1.8691099 | D16: The central objection this pitch must answer
B18: CAPITAL STRUCTURE
B19: Cash and equivalents, FY26A (A$m) | C19: 2290 | D19: A FY26 result, 24-Aug-26
B20: Borrowings, FY26A (A$m) | C20: 828 | D20: E US$600m senior notes translated at spot - VERIFY
B21: Net cash / (net debt) (A$m) | C21: =C19-C20 -> 1462
B22: Enterprise value (A$m) | C22: =C13-C21 -> 16183.6
B23: Target gearing D/(D+E) | C23: 0.1 | D23: E through-cycle target; PLS is currently net cash
B25: COST OF CAPITAL (CAPM inputs prescribed by the case)
B26: Risk-free rate | C26: 0.05 | D26: C FMAA case p.6 - prescribed
B27: Market risk premium | C27: 0.06 | D27: C FMAA case p.6 - prescribed
B28: Equity beta | C28: 0.73 | D28: C FMAA case p.6 - Yahoo 5Y monthly
B29: Cost of equity = Rf + B x MRP | C29: =C26+C28*C27 -> 0.0938
B30: Pre-tax cost of debt | C30: 0.0625 | D30: E indicative senior note coupon - VERIFY
B31: Corporate tax rate | C31: 0.3 | D31: Australian statutory rate
B32: After-tax cost of debt | C32: =C30*(1-C31) -> 0.04375
B33: WACC | C33: =(1-C23)*C29+C23*C32 -> 0.088795
B35: TERMINAL VALUE
B36: Terminal growth rate (scenario-driven) | C36: =CHOOSE($C$8,0.015,0.025,0.03) -> 0.025 | D36: E below long-run Australian nominal GDP growth
B37: Terminal FCFF basis | C37: Final forecast year FCFF grown at TGR
B39: OPERATING DRIVERS
B40: Corporate and admin cost (A$m p.a., FY27 base) | C40: 95 | D40: E
B41: Cost inflation p.a. | C41: 0.025 | D41: E
B42: WA State royalty (% of realised revenue) | C42: 0.05 | D42: WA ad valorem royalty on concentrate - VERIFY rate and basis
B43: D&A as % of prior-year capex (steady state) | C43: 0.85 | D43: E
B44: Net working capital as % of revenue | C44: 0.08 | D44: E
B46: OREBODY AND MINE LIFE (drives the terminal value)
B47: Mineral Resource (Mt) | C47: 446 | D47: A 446Mt at 1.28% Li2O, June-2025 update
...

Sheet Deck
B2: Operating deck
B3: Three scenarios held side by side; the ACTIVE block is what the model reads
B4: PLS Group Limited (ASX: PLS) | Valuation date 5 September 2026 | All figures A$ unless stated
B6: Spodumene concentrate production (kt) | C6: FY24A | D6: FY25A | E6: FY26A | F6: FY27F | G6: FY28F | H6: FY29F | I6: FY30F | J6: FY31F | K6: FY32F | L6: FY33F | M6: FY34F | N6: FY35F | O6: FY36F
B7: Bear case
B8: Pilgangoora (Pilgan plant) | F8: 880 | G8: 880 | H8: 870 | I8: 870 | J8: 860 | K8: 860 | L8: 850 | M8: 850 | N8: 850 | O8: 850
B9: Ngungaju plant | F9: 150 | G9: 170 | H9: 160 | I9: 120 | J9: 120 | K9: 140 | L9: 150 | M9: 160 | N9: 170 | O9: 170
B10: P2000 expansion | F10: 0 | G10: 0 | H10: 0 | I10: 0 | J10: 0 | K10: 0 | L10: 0 | M10: 0 | N10: 0 | O10: 0
B11: Colina, Brazil | F11: 0 | G11: 0 | H11: 0 | I11: 0 | J11: 0 | K11: 0 | L11: 0 | M11: 0 | N11: 0 | O11: 0
B12: Total - Bear | F12: =SUM(F8:F11) -> 1030 | G12: =SUM(G8:G11) -> 1050 | H12: =SUM(H8:H11) -> 1030 | I12: =SUM(I8:I11) -> 990 | J12: =SUM(J8:J11) -> 980 | K12: =SUM(K8:K11) -> 1000 | L12: =SUM(L8:L11) -> 1000 | M12: =SUM(M8:M11) -> 1010 | ... O12: =SUM(O8:O11) -> 1020
B14: Base case
B15: Pilgangoora (Pilgan plant) | F15: 900 | G15: 920 | H15: 920 | I15: 920 | J15: 920 | K15: 920 | L15: 920 | M15: 920 | N15: 920 | O15: 920
B16: Ngungaju plant | F16: 165 | G16: 195 | H16: 195 | I16: 195 | J16: 195 | K16: 195 | L16: 195 | M16: 195 | N16: 195 | O16: 195
B17: P2000 expansion | F17: 0 | G17: 0 | H17: 0 | I17: 250 | J17: 550 | K17: 800 | L17: 885 | M17: 885 | N17: 885 | O17: 885
B18: Colina, Brazil | F18: 0 | G18: 0 | H18: 0 | I18: 0 | J18: 0 | K18: 150 | L18: 350 | M18: 460 | N18: 500 | O18: 500
B19: Total - Base | F19: =SUM(F15:F18) -> 1065 | G19: =SUM(G15:G18) -> 1115 | H19: =SUM(H15:H18) -> 1115 | I19: =SUM(I15:I18) -> 1365 | J19: =SUM(J15:J18) -> 1665 | K19: =SUM(K15:K18) -> 2065 | L19: =SUM(L15:L18) -> 2350 | M19: =SUM(M15:M18) -> 2460 | ... O19: =SUM(O15:O18) -> 2500
B21: Bull case
B22: Pilgangoora (Pilgan plant) | F22: 920 | G22: 960 | H22: 970 | I22: 970 | J22: 970 | K22: 970 | L22: 970 | M22: 970 | N22: 970 | O22: 970
B23: Ngungaju plant | F23: 180 | G23: 205 | H23: 205 | I23: 205 | J23: 205 | K23: 205 | L23: 205 | M23: 205 | N23: 205 | O23: 205
B24: P2000 expansion | F24: 0 | G24: 0 | H24: 120 | I24: 450 | J24: 780 | K24: 925 | L24: 950 | M24: 950 | N24: 950 | O24: 950
B25: Colina, Brazil | F25: 0 | G25: 0 | H25: 0 | I25: 0 | J25: 180 | K25: 380 | L25: 500 | M25: 560 | N25: 560 | O25: 560
B26: Total - Bull | F26: =SUM(F22:F25) -> 1100 | G26: =SUM(G22:G25) -> 1165 | H26: =SUM(H22:H25) -> 1295 | I26: =SUM(I22:I25) -> 1625 | J26: =SUM(J22:J25) -> 2135 | K26: =SUM(K22:K25) -> 2480 | L26: =SUM(L22:L25) -> 2625 | M26: =SUM(M22:M25) -> 2685 | ... O26: =SUM(O22:O25) -> 2685
B28: ACTIVE (driven by Assumptions!C7)
B29: Pilgangoora (Pilgan plant) | F29: =CHOOSE(Assumptions!$C$8,F8,F15,F22) -> 900 | G29: =CHOOSE(Assumptions!$C$8,G8,G15,G22) -> 920 | H29: =CHOOSE(Assumptions!$C$8,H8,H15,H22) -> 920 | I29: =CHOOSE(Assumptions!$C$8,I8,I15,I22) -> 920 | J29: =CHOOSE(Assumptions!$C$8,J8,J15,J22) -> 920 | K29: =CHOOSE(Assumptions!$C$8,K8,K15,K22) -> 920 | L29: =CHOOSE(Assumptions!$C$8,L8,L15,L22) -> 920 | M29: =CHOOSE(Assumptions!$C$8,M8,M15,M22) -> 920 | ... O29: =CHOOSE(Assumptions!$C$8,O8,O15,O22) -> 920
B30: Ngungaju plant | F30: =CHOOSE(Assumptions!$C$8,F9,F16,F23) -> 165 | G30: =CHOOSE(Assumptions!$C$8,G9,G16,G23) -> 195 | H30: =CHOOSE(Assumptions!$C$8,H9,H16,H23) -> 195 | I30: =CHOOSE(Assumptions!$C$8,I9,I16,I23) -> 195 | J30: =CHOOSE(Assumptions!$C$8,J9,J16,J23) -> 195 | K30: =CHOOSE(Assumptions!$C$8,K9,K16,K23) -> 195 | L30: =CHOOSE(Assumptions!$C$8,L9,L16,L23) -> 195 | M30: =CHOOSE(Assumptions!$C$8,M9,M16,M23) -> 195 | ... O30: =CHOOSE(Assumptions!$C$8,O9,O16,O23) -> 195
B31: P2000 expansion | F31: =CHOOSE(Assumptions!$C$8,F10,F17,F24) -> 0 | G31: =CHOOSE(Assumptions!$C$8,G10,G17,G24) -> 0 | H31: =CHOOSE(Assumptions!$C$8,H10,H17,H24) -> 0 | I31: =CHOOSE(Assumptions!$C$8,I10,I17,I24) -> 250 | J31: =CHOOSE(Assumptions!$C$8,J10,J17,J24) -> 550 | K31: =CHOOSE(Assumptions!$C$8,K10,K17,K24) -> 800 | L31: =CHOOSE(Assumptions!$C$8,L10,L17,L24) -> 885 | M31: =CHOOSE(Assumptions!$C$8,M10,M17,M24) -> 885 | ... O31: =CHOOSE(Assumptions!$C$8,O10,O17,O24) -> 885
B32: Colina, Brazil | F32: =CHOOSE(Assumptions!$C$8,F11,F18,F25) -> 0 | G32: =CHOOSE(Assumptions!$C$8,G11,G18,G25) -> 0 | H32: =CHOOSE(Assumptions!$C$8,H11,H18,H25) -> 0 | I32: =CHOOSE(Assumptions!$C$8,I11,I18,I25) -> 0 | J32: =CHOOSE(Assumptions!$C$8,J11,J18,J25) -> 0 | K32: =CHOOSE(Assumptions!$C$8,K11,K18,K25) -> 150 | L32: =CHOOSE(Assumptions!$C$8,L11,L18,L25) -> 350 | M32: =CHOOSE(Assumptions!$C$8,M11,M18,M25) -> 460 | ... O32: =CHOOSE(Assumptions!$C$8,O11,O18,O25) -> 500
B33: Total production (kt) | C33: 725.3 | D33: 755.6 | E33: 879.5 | F33: =SUM(F29:F32) -> 1065 | G33: =SUM(G29:G32) -> 1115 | H33: =SUM(H29:H32) -> 1115 | I33: =SUM(I29:I32) -> 1365 | J33: =SUM(J29:J32) -> 1665 | K33: =SUM(K29:K32) -> 2065 | L33: =SUM(L29:L32) -> 2350 | M33: =SUM(M29:M32) -> 2460 | ... O33: =SUM(O29:O32) -> 2500
B34: Concentrate sold (kt) | C34: 707 | D34: 749 | E34: 891.6 | F34: =F33 -> 1065 | G34: =G33 -> 1115 | H34: =H33 -> 1115 | I34: =I33 -> 1365 | J34: =J33 -> 1665 | K34: =K33 -> 2065 | L34: =L33 -> 2350 | M34: =M33 -> 2460 | ... O34: =O33 -> 2500 | Q34: Forecast assumes sales = production (no inventory build)
B35: Growth in production | D35: =D33/C33-1 -> 0.041775817 | E35: =E33/D33-1 -> 0.16397565 | F35: =F33/E33-1 -> 0.21091529 | G35: =G33/F33-1 -> 0.046948357 | H35: =H33/G33-1 -> 0 | I35: =I33/H33-1 -> 0.22421525 | J35: =J33/I33-1 -> 0.21978022 | K35: =K33/J33-1 -> 0.24024024 | ... O35: =O33/N33-1 -> 0
B37: Realised price (US$/dmt of concentrate) | C37: FY24A | D37: FY25A | E37: FY26A | F37: FY27F | G37: FY28F | H37: FY29F | I37: FY30F | J37: FY31F | K37: FY32F | L37: FY33F | M37: FY34F | N37: FY35F | O37: FY36F
B38: Bear case | F38: 1350 | G38: 1150 | H38: 1050 | I38: 1050 | J38: 1150 | K38: 1250 | L38: 1350 | M38: 1450 | N38: 1500 | O38: 1550
B39: Base case | F39: 1700 | G39: 1780 | H39: 1850 | I39: 1800 | J39: 1750 | K39: 1750 | L39: 1750 | M39: 1750 | N39: 1750 | O39: 1750
B40: Bull case | F40: 2050 | G40: 2400 | H40: 2600 | I40: 2450 | J40: 2300 | K40: 2150 | L40: 2050 | M40: 1975 | N40: 1925 | O40: 1900
B41: ACTIVE realised price (US$/t) | C41: 1116 | D41: 688 | E41: 1488 | F41: =CHOOSE(Assumptions!$C$8,F38,F39,F40) -> 1700 | G41: =CHOOSE(Assumptions!$C$8,G38,G39,G40) -> 1780 | H41: =CHOOSE(Assumptions!$C$8,H38,H39,H40) -> 1850 | I41: =CHOOSE(Assumptions!$C$8,I38,I39,I40) -> 1800 | J41: =CHOOSE(Assumptions!$C$8,J38,J39,J40) -> 1750 | K41: =CHOOSE(Assumptions!$C$8,K38,K39,K40) -> 1750 | L41: =CHOOSE(Assumptions!$C$8,L38,L39,L40) -> 1750 | M41: =CHOOSE(Assumptions!$C$8,M38,M39,M40) -> 1750 | ... O41: =CHOOSE(Assumptions!$C$8,O38,O39,O40) -> 1750
B42: AUD/USD | C42: 0.657 | D42: 0.646 | E42: 0.65 | F42: 0.66 | G42: 0.67 | H42: 0.68 | I42: 0.69 | J42: 0.7 | K42: 0.7 | L42: 0.7 | M42: 0.7 | N42: 0.7 | O42: 0.7
B43: Realised price (A$/t) | C43: =C41/C42 -> 1698.6301 | D43: =D41/D42 -> 1065.0155 | E43: =E41/E42 -> 2289.2308 | F43: =F41/F42 -> 2575.7576 | G43: =G41/G42 -> 2656.7164 | H43: =H41/H42 -> 2720.5882 | I43: =I41/I42 -> 2608.6957 | J43: =J41/J42 -> 2500 | ... O43: =O41/O42 -> 2500
B45: Unit operating cost, FOB (A$/dmt) | C45: FY24A | D45: FY25A | E45: FY26A | F45: FY27F | G45: FY28F | H45: FY29F | I45: FY30F | J45: FY31F | K45: FY32F | L45: FY33F | M45: FY34F | N45: FY35F | O45: FY36F
B46: Bear case | F46: 625 | G46: 645 | H46: 655 | I46: 640 | J46: 625 | K46: 615 | L46: 610 | M46: 610 | N46: 610 | O46: 610
B47: Base case | F47: 600 | G47: 590 | H47: 585 | I47: 580 | J47: 570 | K47: 565 | L47: 565 | M47: 565 | N47: 565 | O47: 565
...

Sheet Revenue Build
B2: Revenue build
B3: Volume x realised price by asset, reconciled to reported revenue
B4: PLS Group Limited (ASX: PLS) | Valuation date 5 September 2026 | All figures A$ unless stated
B6: Volumes by asset (kt) | C6: FY24A | D6: FY25A | E6: FY26A | F6: FY27F | G6: FY28F | H6: FY29F | I6: FY30F | J6: FY31F | K6: FY32F | L6: FY33F | M6: FY34F | N6: FY35F | O6: FY36F
B7: Pilgangoora (Pilgan plant) | F7: =Deck!F29 -> 900 | G7: =Deck!G29 -> 920 | H7: =Deck!H29 -> 920 | I7: =Deck!I29 -> 920 | J7: =Deck!J29 -> 920 | K7: =Deck!K29 -> 920 | L7: =Deck!L29 -> 920 | M7: =Deck!M29 -> 920 | ... O7: =Deck!O29 -> 920
B8: Ngungaju plant | F8: =Deck!F30 -> 165 | G8: =Deck!G30 -> 195 | H8: =Deck!H30 -> 195 | I8: =Deck!I30 -> 195 | J8: =Deck!J30 -> 195 | K8: =Deck!K30 -> 195 | L8: =Deck!L30 -> 195 | M8: =Deck!M30 -> 195 | ... O8: =Deck!O30 -> 195
B9: P2000 expansion | F9: =Deck!F31 -> 0 | G9: =Deck!G31 -> 0 | H9: =Deck!H31 -> 0 | I9: =Deck!I31 -> 250 | J9: =Deck!J31 -> 550 | K9: =Deck!K31 -> 800 | L9: =Deck!L31 -> 885 | M9: =Deck!M31 -> 885 | ... O9: =Deck!O31 -> 885
B10: Colina, Brazil | F10: =Deck!F32 -> 0 | G10: =Deck!G32 -> 0 | H10: =Deck!H32 -> 0 | I10: =Deck!I32 -> 0 | J10: =Deck!J32 -> 0 | K10: =Deck!K32 -> 150 | L10: =Deck!L32 -> 350 | M10: =Deck!M32 -> 460 | ... O10: =Deck!O32 -> 500
B11: Total concentrate sold (kt) | C11: =Deck!C34 -> 707 | D11: =Deck!D34 -> 749 | E11: =Deck!E34 -> 891.6 | F11: =Deck!F34 -> 1065 | G11: =Deck!G34 -> 1115 | H11: =Deck!H34 -> 1115 | I11: =Deck!I34 -> 1365 | J11: =Deck!J34 -> 1665 | ... O11: =Deck!O34 -> 2500
B13: Price realisation | C13: FY24A | D13: FY25A | E13: FY26A | F13: FY27F | G13: FY28F | H13: FY29F | I13: FY30F | J13: FY31F | K13: FY32F | L13: FY33F | M13: FY34F | N13: FY35F | O13: FY36F
B14: Realised price (US$/t) | C14: =Deck!C41 -> 1116 | D14: =Deck!D41 -> 688 | E14: =Deck!E41 -> 1488 | F14: =Deck!F41 -> 1700 | G14: =Deck!G41 -> 1780 | H14: =Deck!H41 -> 1850 | I14: =Deck!I41 -> 1800 | J14: =Deck!J41 -> 1750 | ... O14: =Deck!O41 -> 1750
B15: AUD/USD | C15: =Deck!C42 -> 0.657 | D15: =Deck!D42 -> 0.646 | E15: =Deck!E42 -> 0.65 | F15: =Deck!F42 -> 0.66 | G15: =Deck!G42 -> 0.67 | H15: =Deck!H42 -> 0.68 | I15: =Deck!I42 -> 0.69 | J15: =Deck!J42 -> 0.7 | ... O15: =Deck!O42 -> 0.7
B16: Realised price (A$/t) | C16: =C14/C15 -> 1698.6301 | D16: =D14/D15 -> 1065.0155 | E16: =E14/E15 -> 2289.2308 | F16: =F14/F15 -> 2575.7576 | G16: =G14/G15 -> 2656.7164 | H16: =H14/H15 -> 2720.5882 | I16: =I14/I15 -> 2608.6957 | J16: =J14/J15 -> 2500 | ... O16: =O14/O15 -> 2500
B18: Revenue (A$m) | C18: FY24A | D18: FY25A | E18: FY26A | F18: FY27F | G18: FY28F | H18: FY29F | I18: FY30F | J18: FY31F | K18: FY32F | L18: FY33F | M18: FY34F | N18: FY35F | O18: FY36F
B19: Gross concentrate revenue | C19: =C11*C16/1000 -> 1200.9315 | D19: =D11*D16/1000 -> 797.69659 | E19: =E11*E16/1000 -> 2041.0782 | F19: =F11*F16/1000 -> 2743.1818 | G19: =G11*G16/1000 -> 2962.2388 | H19: =H11*H16/1000 -> 3033.4559 | I19: =I11*I16/1000 -> 3560.8696 | J19: =J11*J16/1000 -> 4162.5 | ... O19: =O11*O16/1000 -> 6250
B20: Freight, moisture and timing adjustment (% of gross) | C20: 0 | D20: 0.036 | E20: 0.0525 | F20: 0.054 | G20: 0.054 | H20: 0.054 | I20: 0.054 | J20: 0.054 | K20: 0.054 | L20: 0.054 | M20: 0.054 | N20: 0.054 | O20: 0.054 | Q20: Calibrated to reported revenue in FY25A and FY26A; held flat at 5.4% across the forecast
B21: Revenue | C21: =C19*(1-C20) -> 1200.9315 | D21: =D19*(1-D20) -> 768.97952 | E21: =E19*(1-E20) -> 1933.9216 | F21: =F19*(1-F20) -> 2595.05 | G21: =G19*(1-G20) -> 2802.2779 | H21: =H19*(1-H20) -> 2869.6493 | I21: =I19*(1-I20) -> 3368.5826 | J21: =J19*(1-J20) -> 3937.725 | ... O21: =O19*(1-O20) -> 5912.5
B22: Memo: reported revenue (A$m) | C22: 1254 | D22: 769 | E22: 1934
B23: Variance to reported | C23: =IFERROR(C21/C22-1,"") -> -0.042319373 | D23: =IFERROR(D21/D22-1,"") -> -2.6635855e-05 | E23: =IFERROR(E21/E22-1,"") -> -4.0563201e-05
B25: The realisation adjustment captures freight to the customer's port, moisture and grade adjustments, and the timing lag between the reference price and shipment.

Sheet Income Statement
B2: Income statement
B3: FY24A-FY36F, A$m
B4: PLS Group Limited (ASX: PLS) | Valuation date 5 September 2026 | All figures A$ unless stated
B6: A$m | C6: FY24A | D6: FY25A | E6: FY26A | F6: FY27F | G6: FY28F | H6: FY29F | I6: FY30F | J6: FY31F | K6: FY32F | L6: FY33F | M6: FY34F | N6: FY35F | O6: FY36F
B7: Revenue | C7: ='Revenue Build'!C21 -> 1200.9315 | D7: ='Revenue Build'!D21 -> 768.97952 | E7: ='Revenue Build'!E21 -> 1933.9216 | F7: ='Revenue Build'!F21 -> 2595.05 | G7: ='Revenue Build'!G21 -> 2802.2779 | H7: ='Revenue Build'!H21 -> 2869.6493 | I7: ='Revenue Build'!I21 -> 3368.5826 | J7: ='Revenue Build'!J21 -> 3937.725 | ... O7: ='Revenue Build'!O21 -> 5912.5
B8: Operating costs (FOB) | C8: =-Deck!C34*Deck!C49/1000 -> -463.085 | D8: =-Deck!D34*Deck!D49/1000 -> -469.623 | E8: =-Deck!E34*Deck!E49/1000 -> -507.3204 | F8: =-Deck!F34*Deck!F49/1000 -> -639 | G8: =-Deck!G34*Deck!G49/1000 -> -657.85 | H8: =-Deck!H34*Deck!H49/1000 -> -652.275 | I8: =-Deck!I34*Deck!I49/1000 -> -791.7 | J8: =-Deck!J34*Deck!J49/1000 -> -949.05 | ... O8: =-Deck!O34*Deck!O49/1000 -> -1412.5
B9: State royalties | C9: =-C7*Assumptions!$C$42 -> -60.046575 | D9: =-D7*Assumptions!$C$42 -> -38.448976 | E9: =-E7*Assumptions!$C$42 -> -96.696078 | F9: =-F7*Assumptions!$C$42 -> -129.7525 | G9: =-G7*Assumptions!$C$42 -> -140.1139 | H9: =-H7*Assumptions!$C$42 -> -143.48246 | I9: =-I7*Assumptions!$C$42 -> -168.42913 | J9: =-J7*Assumptions!$C$42 -> -196.88625 | ... O9: =-O7*Assumptions!$C$42 -> -295.625
B10: Corporate, administration and cost-definition reconciliation | C10: =C27-C7-C8-C9 -> -139.79993 | D10: =D27-D7-D8-D9 -> -163.90754 | E10: =E27-E7-E8-E9 -> -192.90507 | F10: =-Assumptions!$C$40*(1+Assumptions!$C$41)^(0) -> -95 | G10: =-Assumptions!$C$40*(1+Assumptions!$C$41)^(1) -> -97.375 | H10: =-Assumptions!$C$40*(1+Assumptions!$C$41)^(2) -> -99.809375 | I10: =-Assumptions!$C$40*(1+Assumptions!$C$41)^(3) -> -102.30461 | J10: =-Assumptions!$C$40*(1+Assumptions!$C$41)^(4) -> -104.86222 | K10: =-Assumptions!$C$40*(1+Assumptions!$C$41)^(5) -> -107.48378 | L10: =-Assumptions!$C$40*(1+Assumptions!$C$41)^(6) -> -110.17087 | M10: =-Assumptions!$C$40*(1+Assumptions!$C$41)^(7) -> -112.92515 | N10: =-Assumptions!$C$40*(1+Assumptions!$C$41)^(8) -> -115.74828 | O10: =-Assumptions!$C$40*(1+Assumptions!$C$41)^(9) -> -118.64198 | Q10: Historical columns absorb the difference between this simplified cost build and reported underlying EBITDA, so FY24A-FY26A tie exactly.
B11: EBITDA | C11: =SUM(C7:C10) -> 538 | D11: =SUM(D7:D10) -> 97 | E11: =SUM(E7:E10) -> 1137 | F11: =SUM(F7:F10) -> 1731.2975 | G11: =SUM(G7:G10) -> 1906.939 | H11: =SUM(H7:H10) -> 1974.0824 | I11: =SUM(I7:I10) -> 2306.1489 | J11: =SUM(J7:J10) -> 2686.9265 | ... O11: =SUM(O7:O10) -> 4085.733
B12: EBITDA margin | C12: =IFERROR(C11/C7,0) -> 0.44798558 | D12: =IFERROR(D11/D7,0) -> 0.1261412 | E12: =IFERROR(E11/E7,0) -> 0.58792457 | F12: =IFERROR(F11/F7,0) -> 0.66715381 | G12: =IFERROR(G11/G7,0) -> 0.68049604 | H12: =IFERROR(H11/H7,0) -> 0.68791767 | I12: =IFERROR(I11/I7,0) -> 0.68460511 | J12: =IFERROR(J11/J7,0) -> 0.68235505 | ... O12: =IFERROR(O11/O7,0) -> 0.69103307
B13: Depreciation and amortisation | C13: -300 | D13: -330 | E13: -360 | F13: =-'Balance Sheet'!F25 -> -368 | G13: =-'Balance Sheet'!G25 -> -400.66 | H13: =-'Balance Sheet'!H25 -> -455.7841 | I13: =-'Balance Sheet'!I25 -> -520.66893 | J13: =-'Balance Sheet'!J25 -> -548.192 | K13: =-'Balance Sheet'!K25 -> -549.54992 | L13: =-'Balance Sheet'!L25 -> -546.15168 | M13: =-'Balance Sheet'!M25 -> -532.79424 | ... O13: =-'Balance Sheet'!O25 -> -499.54002
B14: EBIT | C14: =C11+C13 -> 238 | D14: =D11+D13 -> -233 | E14: =E11+E13 -> 777 | F14: =F11+F13 -> 1363.2975 | G14: =G11+G13 -> 1506.279 | H14: =H11+H13 -> 1518.2983 | I14: =I11+I13 -> 1785.4799 | J14: =J11+J13 -> 2138.7345 | ... O14: =O11+O13 -> 3586.193
B15: Net interest income / (expense) | C15: -10 | D15: 25 | E15: 40 | F15: ='Balance Sheet'!F26 -> 39.85 | G15: ='Balance Sheet'!G26 -> 53.87608 | H15: ='Balance Sheet'!H26 -> 64.618391 | I15: ='Balance Sheet'!I26 -> 72.859334 | J15: ='Balance Sheet'!J26 -> 87.706254 | K15: ='Balance Sheet'!K26 -> 116.58285 | L15: ='Balance Sheet'!L26 -> 155.79073 | M15: ='Balance Sheet'!M26 -> 206.60204 | ... O15: ='Balance Sheet'!O26 -> 322.50245
B16: Profit before tax | C16: =C14+C15 -> 228 | D16: =D14+D15 -> -208 | E16: =E14+E15 -> 817 | F16: =F14+F15 -> 1403.1475 | G16: =G14+G15 -> 1560.1551 | H16: =H14+H15 -> 1582.9167 | I16: =I14+I15 -> 1858.3393 | J16: =J14+J15 -> 2226.4408 | ... O16: =O14+O15 -> 3908.6955
B17: Income tax expense | C17: =-MAX(0,C16)*Assumptions!$C$31 -> -68.4 | D17: =-MAX(0,D16)*Assumptions!$C$31 -> 0 | E17: =-MAX(0,E16)*Assumptions!$C$31 -> -245.1 | F17: =-MAX(0,F16)*Assumptions!$C$31 -> -420.94425 | G17: =-MAX(0,G16)*Assumptions!$C$31 -> -468.04653 | H17: =-MAX(0,H16)*Assumptions!$C$31 -> -474.87502 | I17: =-MAX(0,I16)*Assumptions!$C$31 -> -557.50178 | J17: =-MAX(0,J16)*Assumptions!$C$31 -> -667.93223 | ... O17: =-MAX(0,O16)*Assumptions!$C$31 -> -1172.6086
B18: NPAT | C18: =C16+C17 -> 159.6 | D18: =D16+D17 -> -208 | E18: =E16+E17 -> 571.9 | F18: =F16+F17 -> 982.20325 | G18: =G16+G17 -> 1092.1086 | H18: =H16+H17 -> 1108.0417 | I18: =I16+I17 -> 1300.8375 | J18: =J16+J17 -> 1558.5085 | ... O18: =O16+O17 -> 2736.0868
B20: Per share and returns | C20: FY24A | D20: FY25A | E20: FY26A | F20: FY27F | G20: FY28F | H20: FY29F | I20: FY30F | J20: FY31F | K20: FY32F | L20: FY33F | M20: FY34F | N20: FY35F | O20: FY36F
B21: EPS (A$) | C21: =C18/Assumptions!$C$12 -> 0.049565217 | D21: =D18/Assumptions!$C$12 -> -0.064596273 | E21: =E18/Assumptions!$C$12 -> 0.1776087 | F21: =F18/Assumptions!$C$12 -> 0.30503207 | G21: =G18/Assumptions!$C$12 -> 0.33916415 | H21: =H18/Assumptions!$C$12 -> 0.34411233 | I21: =I18/Assumptions!$C$12 -> 0.4039868 | J21: =J18/Assumptions!$C$12 -> 0.48400886 | ... O21: =O18/Assumptions!$C$12 -> 0.8497164
B22: Dividend payout ratio | F22: 0.3 | G22: 0.3 | H22: 0.3 | I22: 0.5 | J22: 0.5 | K22: 0.5 | L22: 0.5 | M22: 0.5 | N22: 0.5 | O22: 0.5 | Q22: Policy is 20-30% of free cash flow; we step up to 50% from FY30 once the P2000 build is funded
B23: DPS (A$) | F23: =MAX(0,F21)*F22 -> 0.09150962 | G23: =MAX(0,G21)*G22 -> 0.10174925 | H23: =MAX(0,H21)*H22 -> 0.1032337 | I23: =MAX(0,I21)*I22 -> 0.2019934 | J23: =MAX(0,J21)*J22 -> 0.24200443 | K23: =MAX(0,K21)*K22 -> 0.3187351 | L23: =MAX(0,L21)*L22 -> 0.37517181 | M23: =MAX(0,M21)*M22 -> 0.40195518 | ... O23: =MAX(0,O21)*O22 -> 0.4248582
B24: Total dividends (A$m) | F24: =F23*Assumptions!$C$12 -> 294.66098 | G24: =G23*Assumptions!$C$12 -> 327.63257 | H24: =H23*Assumptions!$C$12 -> 332.41251 | I24: =I23*Assumptions!$C$12 -> 650.41875 | J24: =J23*Assumptions!$C$12 -> 779.25427 | K24: =K23*Assumptions!$C$12 -> 1026.327 | L24: =L23*Assumptions!$C$12 -> 1208.0532 | M24: =M23*Assumptions!$C$12 -> 1294.2957 | ... O24: =O23*Assumptions!$C$12 -> 1368.0434
B25: Dividend yield on last close | F25: =F23/Assumptions!$C$11 -> 0.016698836 | G25: =G23/Assumptions!$C$11 -> 0.018567381 | H25: =H23/Assumptions!$C$11 -> 0.018838266 | I25: =I23/Assumptions!$C$11 -> 0.036860109 | J25: =J23/Assumptions!$C$11 -> 0.044161393 | K25: =K23/Assumptions!$C$11 -> 0.058163339 | L25: =L23/Assumptions!$C$11 -> 0.06846201 | M25: =M23/Assumptions!$C$11 -> 0.073349485 | ... O25: =O23/Assumptions!$C$11 -> 0.077528869
B27: Memo: reported underlying EBITDA (A$m) | C27: 538 | D27: 97 | E27: 1137
B28: Memo: reported NPAT (A$m) | C28: 257.8 | D28: -196 | E28: 526

Sheet Balance Sheet
B2: Balance sheet
B3: FY26A opening position rolled forward to FY36F, A$m
B4: PLS Group Limited (ASX: PLS) | Valuation date 5 September 2026 | All figures A$ unless stated
B6: A$m | C6: FY24A | D6: FY25A | E6: FY26A | F6: FY27F | G6: FY28F | H6: FY29F | I6: FY30F | J6: FY31F | K6: FY32F | L6: FY33F | M6: FY34F | N6: FY35F | O6: FY36F
B7: Drivers
B8: D&A rate on opening PP&E | F8: 0.115 | G8: 0.115 | H8: 0.115 | I8: 0.115 | J8: 0.115 | K8: 0.115 | L8: 0.115 | M8: 0.115 | N8: 0.115 | O8: 0.115 | Q8: E approximates an 8-9 year average remaining asset life
B9: Interest earned on opening cash | F9: 0.04 | G9: 0.04 | H9: 0.04 | I9: 0.04 | J9: 0.04 | K9: 0.04 | L9: 0.04 | M9: 0.04 | N9: 0.04 | O9: 0.04 | Q9: E
B10: Interest paid on opening debt | F10: =Assumptions!$C$29*0+0.0625 -> 0.0625 | G10: =Assumptions!$C$29*0+0.0625 -> 0.0625 | H10: =Assumptions!$C$29*0+0.0625 -> 0.0625 | I10: =Assumptions!$C$29*0+0.0625 -> 0.0625 | J10: =Assumptions!$C$29*0+0.0625 -> 0.0625 | K10: =Assumptions!$C$29*0+0.0625 -> 0.0625 | L10: =Assumptions!$C$29*0+0.0625 -> 0.0625 | M10: =Assumptions!$C$29*0+0.0625 -> 0.0625 | ... O10: =Assumptions!$C$29*0+0.0625 -> 0.0625
B12: Assets
B13: Cash and cash equivalents | E13: =Assumptions!$C$19 -> 2290 | F13: ='Cash Flow'!F23 -> 2640.652 | G13: ='Cash Flow'!G23 -> 2909.2098 | H13: ='Cash Flow'!H23 -> 3115.2333 | I13: ='Cash Flow'!I23 -> 3486.4064 | J13: ='Cash Flow'!J23 -> 4208.3212 | K13: ='Cash Flow'!K23 -> 5188.5182 | L13: ='Cash Flow'!L23 -> 6458.8011 | M13: ='Cash Flow'!M23 -> 7875.079 | ... O13: ='Cash Flow'!O23 -> 10853.895
B14: Net working capital | E14: ='Income Statement'!E7*Assumptions!$C$44 -> 154.71372 | F14: ='Income Statement'!F7*Assumptions!$C$44 -> 207.604 | G14: ='Income Statement'!G7*Assumptions!$C$44 -> 224.18223 | H14: ='Income Statement'!H7*Assumptions!$C$44 -> 229.57194 | I14: ='Income Statement'!I7*Assumptions!$C$44 -> 269.48661 | J14: ='Income Statement'!J7*Assumptions!$C$44 -> 315.018 | K14: ='Income Statement'!K7*Assumptions!$C$44 -> 390.698 | L14: ='Income Statement'!L7*Assumptions!$C$44 -> 444.62 | ... O14: ='Income Statement'!O7*Assumptions!$C$44 -> 473
B15: Property, plant and equipment (net) | E15: 3200 | F15: =E15+Deck!F57-F25 -> 3484 | G15: =F15+Deck!G57-G25 -> 3963.34 | H15: =G15+Deck!H57-H25 -> 4527.5559 | I15: =H15+Deck!I57-I25 -> 4766.887 | J15: =I15+Deck!J57-J25 -> 4778.695 | K15: =J15+Deck!K57-K25 -> 4749.145 | L15: =K15+Deck!L57-L25 -> 4632.9934 | M15: =L15+Deck!M57-M25 -> 4490.1991 | ... O15: =N15+Deck!O57-O25 -> 4214.2862 | Q15: E FY26A net book value - VERIFY against the annual report
B16: Total assets | E16: =SUM(E13:E15) -> 5644.7137 | F16: =SUM(F13:F15) -> 6332.256 | G16: =SUM(G13:G15) -> 7096.732 | H16: =SUM(H13:H15) -> 7872.3612 | I16: =SUM(I13:I15) -> 8522.7799 | J16: =SUM(J13:J15) -> 9302.0342 | K16: =SUM(K13:K15) -> 10328.361 | L16: =SUM(L13:L15) -> 11536.414 | ... O16: =SUM(O13:O15) -> 15541.181
B18: Liabilities and equity
B19: Borrowings | E19: =Assumptions!$C$20 -> 828 | F19: =E19+'Cash Flow'!F20 -> 828 | G19: =F19+'Cash Flow'!G20 -> 828 | H19: =G19+'Cash Flow'!H20 -> 828 | I19: =H19+'Cash Flow'!I20 -> 828 | J19: =I19+'Cash Flow'!J20 -> 828 | K19: =J19+'Cash Flow'!K20 -> 828 | L19: =K19+'Cash Flow'!L20 -> 828 | M19: =L19+'Cash Flow'!M20 -> 828 | ... O19: =N19+'Cash Flow'!O20 -> 828
B20: Shareholders' equity | E20: =E16-E19 -> 4816.7137 | F20: =E20+'Income Statement'!F18-'Income Statement'!F24 -> 5504.256 | G20: =F20+'Income Statement'!G18-'Income Statement'!G24 -> 6268.732 | H20: =G20+'Income Statement'!H18-'Income Statement'!H24 -> 7044.3612 | I20: =H20+'Income Statement'!I18-'Income Statement'!I24 -> 7694.7799 | J20: =I20+'Income Statement'!J18-'Income Statement'!J24 -> 8474.0342 | K20: =J20+'Income Statement'!K18-'Income Statement'!K24 -> 9500.3612 | L20: =K20+'Income Statement'!L18-'Income Statement'!L24 -> 10708.414 | M20: =L20+'Income Statement'!M18-'Income Statement'!M24 -> 12002.71 | ... O20: =N20+'Income Statement'!O18-'Income Statement'!O24 -> 14713.181
B21: Total liabilities and equity | E21: =E19+E20 -> 5644.7137 | F21: =F19+F20 -> 6332.256 | G21: =G19+G20 -> 7096.732 | H21: =H19+H20 -> 7872.3612 | I21: =I19+I20 -> 8522.7799 | J21: =J19+J20 -> 9302.0342 | K21: =K19+K20 -> 10328.361 | L21: =L19+L20 -> 11536.414 | ... O21: =O19+O20 -> 15541.181
B22: Balance check (must be nil) | E22: =E16-E21 -> 0 | F22: =F16-F21 -> 0 | G22: =G16-G21 -> 0 | H22: =H16-H21 -> 0 | I22: =I16-I21 -> 0 | J22: =J16-J21 -> 0 | K22: =K16-K21 -> 0 | L22: =L16-L21 -> 0 | ... O22: =O16-O21 -> 0
B24: Memo
B25: D&A charge | F25: =E15*F8 -> 368 | G25: =F15*G8 -> 400.66 | H25: =G15*H8 -> 455.7841 | I25: =H15*I8 -> 520.66893 | J25: =I15*J8 -> 548.192 | K25: =J15*K8 -> 549.54992 | L25: =K15*L8 -> 546.15168 | M25: =L15*M8 -> 532.79424 | ... O25: =N15*O8 -> 499.54002
B26: Net interest income / (expense) | F26: =E13*F9-E19*F10 -> 39.85 | G26: =F13*G9-F19*G10 -> 53.87608 | H26: =G13*H9-G19*H10 -> 64.618391 | I26: =H13*I9-H19*I10 -> 72.859334 | J26: =I13*J9-I19*J10 -> 87.706254 | K26: =J13*K9-J19*K10 -> 116.58285 | L26: =K13*L9-K19*L10 -> 155.79073 | M26: =L13*M9-L19*M10 -> 206.60204 | ... O26: =N13*O9-N19*O10 -> 322.50245
B27: Net cash / (net debt) | E27: =E13-E19 -> 1462 | F27: =F13-F19 -> 1812.652 | G27: =G13-G19 -> 2081.2098 | H27: =H13-H19 -> 2287.2333 | I27: =I13-I19 -> 2658.4064 | J27: =J13-J19 -> 3380.3212 | K27: =K13-K19 -> 4360.5182 | L27: =L13-L19 -> 5630.8011 | ... O27: =O13-O19 -> 10025.895
B28: Return on equity | F28: =IFERROR('Income Statement'!F18/E20,0) -> 0.20391564 | G28: =IFERROR('Income Statement'!G18/F20,0) -> 0.19841166 | H28: =IFERROR('Income Statement'!H18/G20,0) -> 0.17675691 | I28: =IFERROR('Income Statement'!I18/H20,0) -> 0.18466366 | J28: =IFERROR('Income Statement'!J18/I20,0) -> 0.20254102 | K28: =IFERROR('Income Statement'!K18/J20,0) -> 0.24222867 | L28: =IFERROR('Income Statement'!L18/K20,0) -> 0.25431733 | M28: =IFERROR('Income Statement'!M18/L20,0) -> 0.24173433 | ... O28: =IFERROR('Income Statement'!O18/N20,0) -> 0.205025
B29: Return on invested capital (after tax) | F29: =IFERROR('Income Statement'!F14*(1-Assumptions!$C$31)/(E15+E14),0) -> 0.28446786 | G29: =IFERROR('Income Statement'!G14*(1-Assumptions!$C$31)/(F15+F14),0) -> 0.28561983 | H29: =IFERROR('Income Statement'!H14*(1-Assumptions!$C$31)/(G15+G14),0) -> 0.25380375 | I29: =IFERROR('Income Statement'!I14*(1-Assumptions!$C$31)/(H15+H14),0) -> 0.26272911 | J29: =IFERROR('Income Statement'!J14*(1-Assumptions!$C$31)/(I15+I14),0) -> 0.29726035 | K29: =IFERROR('Income Statement'!K14*(1-Assumptions!$C$31)/(J15+J14),0) -> 0.38695664 | L29: =IFERROR('Income Statement'!L14*(1-Assumptions!$C$31)/(K15+K14),0) -> 0.44885669 | M29: =IFERROR('Income Statement'!M14*(1-Assumptions!$C$31)/(L15+L14),0) -> 0.48132257 | ... O29: =IFERROR('Income Statement'!O14*(1-Assumptions!$C$31)/(N15+N14),0) -> 0.52115957
B31: FY24A and FY25A balance sheets are not modelled; the DCF runs off the FY26A closing position.

Sheet Cash Flow
B2: Cash flow statement
B3: FY26A opening cash rolled forward to FY36F, A$m
B4: PLS Group Limited (ASX: PLS) | Valuation date 5 September 2026 | All figures A$ unless stated
B6: A$m | C6: FY24A | D6: FY25A | E6: FY26A | F6: FY27F | G6: FY28F | H6: FY29F | I6: FY30F | J6: FY31F | K6: FY32F | L6: FY33F | M6: FY34F | N6: FY35F | O6: FY36F
B7: Operating
B8: EBITDA | E8: ='Income Statement'!E11 -> 1137 | F8: ='Income Statement'!F11 -> 1731.2975 | G8: ='Income Statement'!G11 -> 1906.939 | H8: ='Income Statement'!H11 -> 1974.0824 | I8: ='Income Statement'!I11 -> 2306.1489 | J8: ='Income Statement'!J11 -> 2686.9265 | K8: ='Income Statement'!K11 -> 3365.33 | L8: ='Income Statement'!L11 -> 3841.9416 | ... O8: ='Income Statement'!O11 -> 4085.733
B9: Net interest received / (paid) | F9: ='Balance Sheet'!F26 -> 39.85 | G9: ='Balance Sheet'!G26 -> 53.87608 | H9: ='Balance Sheet'!H26 -> 64.618391 | I9: ='Balance Sheet'!I26 -> 72.859334 | J9: ='Balance Sheet'!J26 -> 87.706254 | K9: ='Balance Sheet'!K26 -> 116.58285 | L9: ='Balance Sheet'!L26 -> 155.79073 | M9: ='Balance Sheet'!M26 -> 206.60204 | ... O9: ='Balance Sheet'!O26 -> 322.50245
B10: Tax paid | F10: ='Income Statement'!F17 -> -420.94425 | G10: ='Income Statement'!G17 -> -468.04653 | H10: ='Income Statement'!H17 -> -474.87502 | I10: ='Income Statement'!I17 -> -557.50178 | J10: ='Income Statement'!J17 -> -667.93223 | K10: ='Income Statement'!K17 -> -879.70887 | L10: ='Income Statement'!L17 -> -1035.4742 | M10: ='Income Statement'!M17 -> -1109.3963 | ... O10: ='Income Statement'!O17 -> -1172.6086
B11: Movement in net working capital | F11: =-('Balance Sheet'!F14-'Balance Sheet'!E14) -> -52.890276 | G11: =-('Balance Sheet'!G14-'Balance Sheet'!F14) -> -16.578233 | H11: =-('Balance Sheet'!H14-'Balance Sheet'!G14) -> -5.3897083 | I11: =-('Balance Sheet'!I14-'Balance Sheet'!H14) -> -39.914668 | J11: =-('Balance Sheet'!J14-'Balance Sheet'!I14) -> -45.531391 | K11: =-('Balance Sheet'!K14-'Balance Sheet'!J14) -> -75.68 | L11: =-('Balance Sheet'!L14-'Balance Sheet'!K14) -> -53.922 | M11: =-('Balance Sheet'!M14-'Balance Sheet'!L14) -> -20.812 | ... O11: =-('Balance Sheet'!O14-'Balance Sheet'!N14) -> 0
B12: Operating cash flow | F12: =SUM(F8:F11) -> 1297.313 | G12: =SUM(G8:G11) -> 1476.1903 | H12: =SUM(H8:H11) -> 1558.4361 | I12: =SUM(I8:I11) -> 1781.5918 | J12: =SUM(J8:J11) -> 2061.1692 | K12: =SUM(K8:K11) -> 2526.5239 | L12: =SUM(L8:L11) -> 2908.3362 | M12: =SUM(M8:M11) -> 3100.5736 | ... O12: =SUM(O8:O11) -> 3235.6268
B14: Investing
B15: Capital expenditure | E15: =-Deck!E57 -> -328 | F15: =-Deck!F57 -> -652 | G15: =-Deck!G57 -> -880 | H15: =-Deck!H57 -> -1020 | I15: =-Deck!I57 -> -760 | J15: =-Deck!J57 -> -560 | K15: =-Deck!K57 -> -520 | L15: =-Deck!L57 -> -430 | ... O15: =-Deck!O57 -> -370
B16: Free cash flow to the firm (pre-financing) | F16: =F12+F15 -> 645.31297 | G16: =G12+G15 -> 596.19033 | H16: =H12+H15 -> 538.43609 | I16: =I12+I15 -> 1021.5918 | J16: =J12+J15 -> 1501.1692 | K16: =K12+K15 -> 2006.5239 | L16: =L12+L15 -> 2478.3362 | M16: =M12+M15 -> 2710.5736 | ... O16: =O12+O15 -> 2865.6268
B18: Financing
B19: Dividends paid | F19: =-'Income Statement'!F24 -> -294.66098 | G19: =-'Income Statement'!G24 -> -327.63257 | H19: =-'Income Statement'!H24 -> -332.41251 | I19: =-'Income Statement'!I24 -> -650.41875 | J19: =-'Income Statement'!J24 -> -779.25427 | K19: =-'Income Statement'!K24 -> -1026.327 | L19: =-'Income Statement'!L24 -> -1208.0532 | M19: =-'Income Statement'!M24 -> -1294.2957 | ... O19: =-'Income Statement'!O24 -> -1368.0434
B20: Net debt drawn / (repaid) | F20: 0 | G20: 0 | H20: 0 | I20: 0 | J20: 0 | K20: 0 | L20: 0 | M20: 0 | N20: 0 | O20: 0 | Q20: E base case assumes the US$600m notes are refinanced at maturity
B21: Net movement in cash | F21: =F16+F19+F20 -> 350.652 | G21: =G16+G19+G20 -> 268.55776 | H21: =H16+H19+H20 -> 206.02358 | I21: =I16+I19+I20 -> 371.17301 | J21: =J16+J19+J20 -> 721.91488 | K21: =K16+K19+K20 -> 980.19694 | L21: =L16+L19+L20 -> 1270.2829 | M21: =M16+M19+M20 -> 1416.2779 | ... O21: =O16+O19+O20 -> 1497.5834
B22: Opening cash | F22: ='Balance Sheet'!E13 -> 2290 | G22: ='Balance Sheet'!F13 -> 2640.652 | H22: ='Balance Sheet'!G13 -> 2909.2098 | I22: ='Balance Sheet'!H13 -> 3115.2333 | J22: ='Balance Sheet'!I13 -> 3486.4064 | K22: ='Balance Sheet'!J13 -> 4208.3212 | L22: ='Balance Sheet'!K13 -> 5188.5182 | M22: ='Balance Sheet'!L13 -> 6458.8011 | ... O22: ='Balance Sheet'!N13 -> 9356.3113
B23: Closing cash | F23: =F22+F21 -> 2640.652 | G23: =G22+G21 -> 2909.2098 | H23: =H22+H21 -> 3115.2333 | I23: =I22+I21 -> 3486.4064 | J23: =J22+J21 -> 4208.3212 | K23: =K22+K21 -> 5188.5182 | L23: =L22+L21 -> 6458.8011 | M23: =M22+M21 -> 7875.079 | ... O23: =O22+O21 -> 10853.895
B25: Tax paid is shown equal to the accrued charge; PLS carries franking credits and tax losses that in practice defer cash tax.

Sheet DCF
B2: Discounted cash flow
B3: Unlevered FCFF for the ACTIVE scenario, discounted at WACC on a mid-year convention
B4: PLS Group Limited (ASX: PLS) | Valuation date 5 September 2026 | All figures A$ unless stated
B6: A$m | C6: FY24A | D6: FY25A | E6: FY26A | F6: FY27F | G6: FY28F | H6: FY29F | I6: FY30F | J6: FY31F | K6: FY32F | L6: FY33F | M6: FY34F | N6: FY35F | O6: FY36F
B7: EBIT | F7: ='Income Statement'!F14 -> 1363.2975 | G7: ='Income Statement'!G14 -> 1506.279 | H7: ='Income Statement'!H14 -> 1518.2983 | I7: ='Income Statement'!I14 -> 1785.4799 | J7: ='Income Statement'!J14 -> 2138.7345 | K7: ='Income Statement'!K14 -> 2815.78 | L7: ='Income Statement'!L14 -> 3295.7899 | M7: ='Income Statement'!M14 -> 3491.3856 | ... O7: ='Income Statement'!O14 -> 3586.193
B8: Less: tax on EBIT | F8: =-MAX(0,F7)*Assumptions!$C$31 -> -408.98925 | G8: =-MAX(0,G7)*Assumptions!$C$31 -> -451.8837 | H8: =-MAX(0,H7)*Assumptions!$C$31 -> -455.4895 | I8: =-MAX(0,I7)*Assumptions!$C$31 -> -535.64398 | J8: =-MAX(0,J7)*Assumptions!$C$31 -> -641.62036 | K8: =-MAX(0,K7)*Assumptions!$C$31 -> -844.73401 | L8: =-MAX(0,L7)*Assumptions!$C$31 -> -988.73698 | M8: =-MAX(0,M7)*Assumptions!$C$31 -> -1047.4157 | ... O8: =-MAX(0,O7)*Assumptions!$C$31 -> -1075.8579
B9: NOPAT | F9: =F7+F8 -> 954.30825 | G9: =G7+G8 -> 1054.3953 | H9: =H7+H8 -> 1062.8088 | I9: =I7+I8 -> 1249.836 | J9: =J7+J8 -> 1497.1142 | K9: =K7+K8 -> 1971.046 | L9: =L7+L8 -> 2307.053 | M9: =M7+M8 -> 2443.9699 | ... O9: =O7+O8 -> 2510.3351
B10: Add back: D&A | F10: ='Balance Sheet'!F25 -> 368 | G10: ='Balance Sheet'!G25 -> 400.66 | H10: ='Balance Sheet'!H25 -> 455.7841 | I10: ='Balance Sheet'!I25 -> 520.66893 | J10: ='Balance Sheet'!J25 -> 548.192 | K10: ='Balance Sheet'!K25 -> 549.54992 | L10: ='Balance Sheet'!L25 -> 546.15168 | M10: ='Balance Sheet'!M25 -> 532.79424 | ... O10: ='Balance Sheet'!O25 -> 499.54002
B11: Less: capital expenditure | F11: =-Deck!F57 -> -652 | G11: =-Deck!G57 -> -880 | H11: =-Deck!H57 -> -1020 | I11: =-Deck!I57 -> -760 | J11: =-Deck!J57 -> -560 | K11: =-Deck!K57 -> -520 | L11: =-Deck!L57 -> -430 | M11: =-Deck!M57 -> -390 | ... O11: =-Deck!O57 -> -370
B12: Less: increase in net working capital | F12: ='Cash Flow'!F11 -> -52.890276 | G12: ='Cash Flow'!G11 -> -16.578233 | H12: ='Cash Flow'!H11 -> -5.3897083 | I12: ='Cash Flow'!I11 -> -39.914668 | J12: ='Cash Flow'!J11 -> -45.531391 | K12: ='Cash Flow'!K11 -> -75.68 | L12: ='Cash Flow'!L11 -> -53.922 | M12: ='Cash Flow'!M11 -> -20.812 | ... O12: ='Cash Flow'!O11 -> 0
B13: Free cash flow to the firm | F13: =F9+F10+F11+F12 -> 617.41797 | G13: =G9+G10+G11+G12 -> 558.47708 | H13: =H9+H10+H11+H12 -> 493.20322 | I13: =I9+I10+I11+I12 -> 970.59022 | J13: =J9+J10+J11+J12 -> 1439.7748 | K13: =K9+K10+K11+K12 -> 1924.916 | L13: =L9+L10+L11+L12 -> 2369.2826 | M13: =M9+M10+M11+M12 -> 2565.9522 | ... O13: =O9+O10+O11+O12 -> 2639.8751
B14: Discount period (mid-year, years) | F14: 0.5 | G14: 1.5 | H14: 2.5 | I14: 3.5 | J14: 4.5 | K14: 5.5 | L14: 6.5 | M14: 7.5 | N14: 8.5 | O14: 9.5
B15: Discount factor | F15: =1/(1+Assumptions!$C$33)^F14 -> 0.95835617 | G15: =1/(1+Assumptions!$C$33)^G14 -> 0.8801989 | H15: =1/(1+Assumptions!$C$33)^H14 -> 0.80841564 | I15: =1/(1+Assumptions!$C$33)^I14 -> 0.74248654 | J15: =1/(1+Assumptions!$C$33)^J14 -> 0.6819342 | K15: =1/(1+Assumptions!$C$33)^K14 -> 0.6263201 | L15: =1/(1+Assumptions!$C$33)^L14 -> 0.57524153 | M15: =1/(1+Assumptions!$C$33)^M14 -> 0.52832859 | ... O15: =1/(1+Assumptions!$C$33)^O14 -> 0.44566844
B16: PV of FCFF | F16: =F13*F15 -> 591.70632 | G16: =G13*G15 -> 491.57091 | H16: =H13*H15 -> 398.7132 | I16: =I13*I15 -> 720.65018 | J16: =J13*J15 -> 981.83166 | K16: =K13*K15 -> 1205.6136 | L16: =L13*L15 -> 1362.9098 | M16: =M13*M15 -> 1355.6659 | ... O16: =O13*O15 -> 1176.509
B18: Enterprise and equity value
B19: Sum of PV of explicit forecast FCFF | C19: =SUM(F16:O16) -> 9565.9087
B20: Terminal growth rate | C20: =Assumptions!$C$36 -> 0.025
B21: Terminal year FCFF | C21: =O13 -> 2639.8751
B22: Cumulative ore mined to FY36 (Mt) | C22: =SUM(Deck!F34:O34)/1000/Assumptions!$C$54 -> 103.96002
B23: Ore base remaining after FY36 (Mt) | C23: =MAX(0,Assumptions!$C$50-C22) -> 230.53998
B24: Terminal mining rate (Mt ore p.a.) | C24: =Deck!O34/1000/Assumptions!$C$54 -> 14.280222
B25: Remaining mine life (years) | C25: =MIN(Assumptions!$C$55,IFERROR(C23/C24,0)) -> 16.144006 | E25: The terminal value is an annuity over remaining ore, not a perpetuity: an orebody is finite
B26: Terminal annuity factor | C26: =(1-(1+Assumptions!$C$33)^-C25)/Assumptions!$C$33 -> 8.4098716
B27: Terminal value at end of forecast | C27: =C21*C26 -> 22201.011
B28: PV of terminal value | C28: =C27*O15 -> 9894.2898
B29: Enterprise value | C29: =C19+C28 -> 19460.198
B30: Terminal value as % of EV | C30: =C28/C29 -> 0.50843725 | E30: A lower share means less of the answer rests on the terminal assumption
B31: Add: net cash / (net debt) | C31: =Assumptions!$C$21 -> 1462
B32: Equity value | C32: =C29+C31 -> 20922.198
B33: Shares on issue (m) | C33: =Assumptions!$C$12 -> 3220
B34: Value per share (A$) | C34: =C32/C33 -> 6.4975772
B35: Last close (A$) | C35: =Assumptions!$C$11 -> 5.48
B36: Implied upside / (downside) | C36: =C34/C35-1 -> 0.18568926
B38: Mid-year convention assumes cash flows arrive evenly through each financial year. The stub from the 5-Sep-26 valuation date to 30-Jun-27 is not discounted separately; the effect is immaterial at this WACC.

Sheet Scenario Engine
B2: Scenario engine
B3: A compact FCFF for each case, computed directly off the Deck's three scenario blocks, so all three values are live at once. The detailed statements show whichever case the switch selects.
B4: PLS Group Limited (ASX: PLS) | Valuation date 5 September 2026 | All figures A$ unless stated
B6: BEAR CASE (A$m unless stated) | C6: FY24A | D6: FY25A | E6: FY26A | F6: FY27F | G6: FY28F | H6: FY29F | I6: FY30F | J6: FY31F | K6: FY32F | L6: FY33F | M6: FY34F | N6: FY35F | O6: FY36F
B7: Concentrate sold (kt) | F7: =Deck!F12 -> 1030 | G7: =Deck!G12 -> 1050 | H7: =Deck!H12 -> 1030 | I7: =Deck!I12 -> 990 | J7: =Deck!J12 -> 980 | K7: =Deck!K12 -> 1000 | L7: =Deck!L12 -> 1000 | M7: =Deck!M12 -> 1010 | ... O7: =Deck!O12 -> 1020
B8: Realised price (US$/t) | F8: =Deck!F38 -> 1350 | G8: =Deck!G38 -> 1150 | H8: =Deck!H38 -> 1050 | I8: =Deck!I38 -> 1050 | J8: =Deck!J38 -> 1150 | K8: =Deck!K38 -> 1250 | L8: =Deck!L38 -> 1350 | M8: =Deck!M38 -> 1450 | ... O8: =Deck!O38 -> 1550
B9: Realised price (A$/t) | F9: =F8/Deck!F42 -> 2045.4545 | G9: =G8/Deck!G42 -> 1716.4179 | H9: =H8/Deck!H42 -> 1544.1176 | I9: =I8/Deck!I42 -> 1521.7391 | J9: =J8/Deck!J42 -> 1642.8571 | K9: =K8/Deck!K42 -> 1785.7143 | L9: =L8/Deck!L42 -> 1928.5714 | M9: =M8/Deck!M42 -> 2071.4286 | ... O9: =O8/Deck!O42 -> 2214.2857
B10: Unit operating cost (A$/t) | F10: =Deck!F46 -> 625 | G10: =Deck!G46 -> 645 | H10: =Deck!H46 -> 655 | I10: =Deck!I46 -> 640 | J10: =Deck!J46 -> 625 | K10: =Deck!K46 -> 615 | L10: =Deck!L46 -> 610 | M10: =Deck!M46 -> 610 | ... O10: =Deck!O46 -> 610
B11: Revenue | F11: =F7*F9/1000*(1-'Revenue Build'!F20) -> 1993.05 | G11: =G7*G9/1000*(1-'Revenue Build'!G20) -> 1704.9179 | H11: =H7*H9/1000*(1-'Revenue Build'!H20) -> 1504.5574 | I11: =I7*I9/1000*(1-'Revenue Build'!I20) -> 1425.1696 | J11: =J7*J9/1000*(1-'Revenue Build'!J20) -> 1523.06 | K11: =K7*K9/1000*(1-'Revenue Build'!K20) -> 1689.2857 | L11: =L7*L9/1000*(1-'Revenue Build'!L20) -> 1824.4286 | M11: =M7*M9/1000*(1-'Revenue Build'!M20) -> 1979.1671 | ... O11: =O7*O9/1000*(1-'Revenue Build'!O20) -> 2136.6086
B12: Operating costs | F12: =-F7*F10/1000 -> -643.75 | G12: =-G7*G10/1000 -> -677.25 | H12: =-H7*H10/1000 -> -674.65 | I12: =-I7*I10/1000 -> -633.6 | J12: =-J7*J10/1000 -> -612.5 | K12: =-K7*K10/1000 -> -615 | L12: =-L7*L10/1000 -> -610 | M12: =-M7*M10/1000 -> -616.1 | ... O12: =-O7*O10/1000 -> -622.2
B13: Royalties | F13: =-F11*Assumptions!$C$42 -> -99.6525 | G13: =-G11*Assumptions!$C$42 -> -85.245896 | H13: =-H11*Assumptions!$C$42 -> -75.227868 | I13: =-I11*Assumptions!$C$42 -> -71.258478 | J13: =-J11*Assumptions!$C$42 -> -76.153 | K13: =-K11*Assumptions!$C$42 -> -84.464286 | L13: =-L11*Assumptions!$C$42 -> -91.221429 | M13: =-M11*Assumptions!$C$42 -> -98.958357 | ... O13: =-O11*Assumptions!$C$42 -> -106.83043
B14: Corporate and admin | F14: =-Assumptions!$C$40*(1+Assumptions!$C$41)^(0) -> -95 | G14: =-Assumptions!$C$40*(1+Assumptions!$C$41)^(1) -> -97.375 | H14: =-Assumptions!$C$40*(1+Assumptions!$C$41)^(2) -> -99.809375 | I14: =-Assumptions!$C$40*(1+Assumptions!$C$41)^(3) -> -102.30461 | J14: =-Assumptions!$C$40*(1+Assumptions!$C$41)^(4) -> -104.86222 | K14: =-Assumptions!$C$40*(1+Assumptions!$C$41)^(5) -> -107.48378 | L14: =-Assumptions!$C$40*(1+Assumptions!$C$41)^(6) -> -110.17087 | M14: =-Assumptions!$C$40*(1+Assumptions!$C$41)^(7) -> -112.92515 | N14: =-Assumptions!$C$40*(1+Assumptions!$C$41)^(8) -> -115.74828 | O14: =-Assumptions!$C$40*(1+Assumptions!$C$41)^(9) -> -118.64198
B15: EBITDA | F15: =SUM(F11:F14) -> 1154.6475 | G15: =SUM(G11:G14) -> 845.04701 | H15: =SUM(H11:H14) -> 654.87011 | I15: =SUM(I11:I14) -> 618.00648 | J15: =SUM(J11:J14) -> 729.54478 | K15: =SUM(K11:K14) -> 882.33765 | L15: =SUM(L11:L14) -> 1013.0363 | M15: =SUM(M11:M14) -> 1151.1836 | ... O15: =SUM(O11:O14) -> 1288.9362
B16: Capital expenditure | F16: =Deck!F54 -> 620 | G16: =Deck!G54 -> 400 | H16: =Deck!H54 -> 340 | I16: =Deck!I54 -> 320 | J16: =Deck!J54 -> 300 | K16: =Deck!K54 -> 295 | L16: =Deck!L54 -> 290 | M16: =Deck!M54 -> 290 | ... O16: =Deck!O54 -> 290
B17: PP&E (closing) | F17: ='Balance Sheet'!E15+F16-F18 -> 3452 | G17: =F17+G16-G18 -> 3455.02 | H17: =G17+H16-H18 -> 3397.6927 | I17: =H17+I16-I18 -> 3326.958 | J17: =I17+J16-J18 -> 3244.3579 | K17: =J17+K16-K18 -> 3166.2567 | L17: =K17+L16-L18 -> 3092.1372 | M17: =L17+M16-M18 -> 3026.5414 | N17: =M17+N16-N18 -> 2968.4891 | O17: =N17+O16-O18 -> 2917.1129
B18: D&A | F18: ='Balance Sheet'!E15*'Balance Sheet'!F8 -> 368 | G18: =F17*'Balance Sheet'!F8 -> 396.98 | H18: =G17*'Balance Sheet'!F8 -> 397.3273 | I18: =H17*'Balance Sheet'!F8 -> 390.73466 | J18: =I17*'Balance Sheet'!F8 -> 382.60017 | K18: =J17*'Balance Sheet'!F8 -> 373.10115 | L18: =K17*'Balance Sheet'!F8 -> 364.11952 | M18: =L17*'Balance Sheet'!F8 -> 355.59578 | N18: =M17*'Balance Sheet'!F8 -> 348.05226 | O18: =N17*'Balance Sheet'!F8 -> 341.37625
B19: EBIT | F19: =F15-F18 -> 786.6475 | G19: =G15-G18 -> 448.06701 | H19: =H15-H18 -> 257.54281 | I19: =I15-I18 -> 227.27182 | J19: =J15-J18 -> 346.9446 | K19: =K15-K18 -> 509.23649 | L19: =L15-L18 -> 648.91675 | M19: =M15-M18 -> 795.58786 | ... O19: =O15-O18 -> 947.55991
B20: NOPAT | F20: =F19*(1-Assumptions!$C$31) -> 550.65325 | G20: =G19*(1-Assumptions!$C$31) -> 313.64691 | H20: =H19*(1-Assumptions!$C$31) -> 180.27997 | I20: =I19*(1-Assumptions!$C$31) -> 159.09027 | J20: =J19*(1-Assumptions!$C$31) -> 242.86122 | K20: =K19*(1-Assumptions!$C$31) -> 356.46555 | L20: =L19*(1-Assumptions!$C$31) -> 454.24172 | M20: =M19*(1-Assumptions!$C$31) -> 556.9115 | ... O20: =O19*(1-Assumptions!$C$31) -> 663.29194
B21: Movement in net working capital | F21: =-(F11*Assumptions!$C$44-'Balance Sheet'!E14) -> -4.7302759 | G21: =-(G11*Assumptions!$C$44-F11*Assumptions!$C$44) -> 23.050567 | H21: =-(H11*Assumptions!$C$44-G11*Assumptions!$C$44) -> 16.028845 | I21: =-(I11*Assumptions!$C$44-H11*Assumptions!$C$44) -> 6.351023 | J21: =-(J11*Assumptions!$C$44-I11*Assumptions!$C$44) -> -7.8312348 | K21: =-(K11*Assumptions!$C$44-J11*Assumptions!$C$44) -> -13.298057 | L21: =-(L11*Assumptions!$C$44-K11*Assumptions!$C$44) -> -10.811429 | M21: =-(M11*Assumptions!$C$44-L11*Assumptions!$C$44) -> -12.379086 | N21: =-(N11*Assumptions!$C$44-M11*Assumptions!$C$44) -> -7.0814857 | O21: =-(O11*Assumptions!$C$44-N11*Assumptions!$C$44) -> -5.5138286
B22: FCFF | F22: =F20+F18-F16+F21 -> 293.92297 | G22: =G20+G18-G16+G21 -> 333.67748 | H22: =H20+H18-H16+H21 -> 253.63611 | I22: =I20+I18-I16+I21 -> 236.17596 | J22: =J20+J18-J16+J21 -> 317.63016 | K22: =K20+K18-K16+K21 -> 421.26864 | L22: =L20+L18-L16+L21 -> 517.54982 | M22: =M20+M18-M16+M21 -> 610.12819 | ... O22: =O20+O18-O16+O21 -> 709.15436
B23: Discount factor | F23: =1/(1+Assumptions!$C$33)^(DCF!F14) -> 0.95835617 | G23: =1/(1+Assumptions!$C$33)^(DCF!G14) -> 0.8801989 | H23: =1/(1+Assumptions!$C$33)^(DCF!H14) -> 0.80841564 | I23: =1/(1+Assumptions!$C$33)^(DCF!I14) -> 0.74248654 | J23: =1/(1+Assumptions!$C$33)^(DCF!J14) -> 0.6819342 | K23: =1/(1+Assumptions!$C$33)^(DCF!K14) -> 0.6263201 | L23: =1/(1+Assumptions!$C$33)^(DCF!L14) -> 0.57524153 | M23: =1/(1+Assumptions!$C$33)^(DCF!M14) -> 0.52832859 | ... O23: =1/(1+Assumptions!$C$33)^(DCF!O14) -> 0.44566844
B24: PV of FCFF | F24: =F22*F23 -> 281.68289 | G24: =G22*G23 -> 293.70255 | H24: =H22*H23 -> 205.0434 | I24: =I22*I23 -> 175.35747 | J24: =J22*J23 -> 216.60287 | K24: =K22*K23 -> 263.84902 | L24: =L22*L23 -> 297.71615 | M24: =M22*M23 -> 322.34817 | ... O24: =O22*O23 -> 316.04772
B25: PV of explicit FCFF | C25: =SUM(F24:O24) -> 2695.415
B26: Terminal growth | C26: 0.015
B27: Cumulative ore mined to FY36 (Mt) | C27: =SUM(F7:O7)/1000/Assumptions!$C$54 -> 57.863459
B28: Ore base remaining after FY36 (Mt) | C28: =MAX(0,Assumptions!$C$50-C27) -> 276.63654
B29: Terminal mining rate (Mt ore p.a.) | C29: =O7/1000/Assumptions!$C$54 -> 5.8263305
B30: Remaining mine life (years) | C30: =MIN(Assumptions!$C$55,IFERROR(C28/C29,0)) -> 25
B31: Terminal annuity factor | C31: =(1-(1+Assumptions!$C$33)^-C30)/Assumptions!$C$33 -> 9.9192586
B32: PV of terminal value | C32: =O22*C31*O23 -> 3134.959
B33: Memo: growing perpetuity alternative | C33: =O22*(1+C26)/(Assumptions!$C$33-C26)*O23 -> 4347.0212
B34: Enterprise value | C34: =C25+C32 -> 5830.3741
B35: Net cash | C35: =Assumptions!$C$21 -> 1462
B36: Equity value | C36: =C34+C35 -> 7292.3741
B37: Value per share (A$) | C37: =C36/Assumptions!$C$12 -> 2.2647124
B38: Upside to last close | C38: =C37/Assumptions!$C$11-1 -> -0.58673131
B41: BASE CASE (A$m unless stated) | C41: FY24A | D41: FY25A | E41: FY26A | F41: FY27F | G41: FY28F | H41: FY29F | I41: FY30F | J41: FY31F | K41: FY32F | L41: FY33F | M41: FY34F | N41: FY35F | O41: FY36F
B42: Concentrate sold (kt) | F42: =Deck!F19 -> 1065 | G42: =Deck!G19 -> 1115 | H42: =Deck!H19 -> 1115 | I42: =Deck!I19 -> 1365 | J42: =Deck!J19 -> 1665 | K42: =Deck!K19 -> 2065 | L42: =Deck!L19 -> 2350 | M42: =Deck!M19 -> 2460 | ... O42: =Deck!O19 -> 2500
B43: Realised price (US$/t) | F43: =Deck!F39 -> 1700 | G43: =Deck!G39 -> 1780 | H43: =Deck!H39 -> 1850 | I43: =Deck!I39 -> 1800 | J43: =Deck!J39 -> 1750 | K43: =Deck!K39 -> 1750 | L43: =Deck!L39 -> 1750 | M43: =Deck!M39 -> 1750 | ... O43: =Deck!O39 -> 1750
B44: Realised price (A$/t) | F44: =F43/Deck!F42 -> 2575.7576 | G44: =G43/Deck!G42 -> 2656.7164 | H44: =H43/Deck!H42 -> 2720.5882 | I44: =I43/Deck!I42 -> 2608.6957 | J44: =J43/Deck!J42 -> 2500 | K44: =K43/Deck!K42 -> 2500 | L44: =L43/Deck!L42 -> 2500 | M44: =M43/Deck!M42 -> 2500 | ... O44: =O43/Deck!O42 -> 2500
...

Sheet Scenario Summary
B2: Scenario summary
B3: All three cases valued live, then probability weighted
B4: PLS Group Limited (ASX: PLS) | Valuation date 5 September 2026 | All figures A$ unless stated
C6: Bear | D6: Base | E6: Bull | F6: Weighted
B7: Probability weighting | C7: 0.25 | D7: 0.5 | E7: 0.25 | F7: =SUM(C7:E7) -> 1
B8: Enterprise value (A$m) | C8: ='Scenario Engine'!$C$34 -> 5830.3741 | D8: ='Scenario Engine'!$C$69 -> 19460.198 | E8: ='Scenario Engine'!$C$104 -> 27306.598 | F8: =SUMPRODUCT(C8:E8,C$7:E$7) -> 18014.342
B9: Equity value (A$m) | C9: ='Scenario Engine'!$C$36 -> 7292.3741 | D9: ='Scenario Engine'!$C$71 -> 20922.198 | E9: ='Scenario Engine'!$C$106 -> 28768.598 | F9: =SUMPRODUCT(C9:E9,C$7:E$7) -> 19476.342
B10: Value per share (A$) | C10: ='Scenario Engine'!$C$37 -> 2.2647124 | D10: ='Scenario Engine'!$C$72 -> 6.4975772 | E10: ='Scenario Engine'!$C$107 -> 8.9343473 | F10: =SUMPRODUCT(C10:E10,C$7:E$7) -> 6.0485535
B11: Upside / (downside) to last close | C11: ='Scenario Engine'!$C$38 -> -0.58673131 | D11: ='Scenario Engine'!$C$73 -> 0.18568926 | E11: ='Scenario Engine'!$C$108 -> 0.63035535 | F11: =SUMPRODUCT(C11:E11,C$7:E$7) -> 0.10375064
B13: Operating metrics at FY30
B14: Concentrate sold (kt) | C14: ='Scenario Engine'!I7 -> 990 | D14: ='Scenario Engine'!I42 -> 1365 | E14: ='Scenario Engine'!I77 -> 1625
B15: Realised price (US$/t) | C15: ='Scenario Engine'!I8 -> 1050 | D15: ='Scenario Engine'!I43 -> 1800 | E15: ='Scenario Engine'!I78 -> 2450
B16: Unit cost (A$/t) | C16: ='Scenario Engine'!I10 -> 640 | D16: ='Scenario Engine'!I45 -> 580 | E16: ='Scenario Engine'!I80 -> 540
B17: EBITDA (A$m) | C17: ='Scenario Engine'!I15 -> 618.00648 | D17: ='Scenario Engine'!I50 -> 2306.1489 | E17: ='Scenario Engine'!I85 -> 4205.6293
B19: Narrative
B20: Bear | C20: Restart supply from Bald Hill, Finniss and Jianxiawo overwhelms demand. Price reverts toward the 90th-percentile cash cost. No P2000 FID, no Colina, Ngungaju re-idled from FY30.
B21: Base | C21: Prices ease from the June-2026 quarter peak as restart tonnes land, then recover as the surplus narrows. P2000 is sanctioned in late 2026 for first ore mid-2029; Colina follows the Dec-2027 study.
B22: Bull | C22: The 2027-29 deficit called by Fastmarkets, Morgan Stanley and UBS arrives. Prices clear at the level needed to fund new supply. P2000 and Colina both proceed, on schedule.

Sheet Sensitivity
B2: Sensitivity analysis
B3: Base-case value per share under alternative cost of capital, growth, price and cost
B4: PLS Group Limited (ASX: PLS) | Valuation date 5 September 2026 | All figures A$ unless stated
B6: 1. Value per share (A$) - WACC vs remaining mine life
B7: Remaining mine life (yrs) \ WACC | C7: 0.0788 | D7: 0.0838 | E7: 0.0888 | F7: 0.0938 | G7: 0.0988
B8: 10 | C8: =(SUMPRODUCT('Scenario Engine'!F57:O57,1/(1+C$7)^DCF!F14:O14)+'Scenario Engine'!O57*(1-(1+C$7)^-$B8)/C$7/(1+C$7)^DCF!O14+Assumptions!$C$21)/Assumptions!$C$12 -> 6.2833439 | D8: =(SUMPRODUCT('Scenario Engine'!F57:O57,1/(1+D$7)^DCF!F14:O14)+'Scenario Engine'!O57*(1-(1+D$7)^-$B8)/D$7/(1+D$7)^DCF!O14+Assumptions!$C$21)/Assumptions!$C$12 -> 6.0249514 | E8: =(SUMPRODUCT('Scenario Engine'!F57:O57,1/(1+E$7)^DCF!F14:O14)+'Scenario Engine'!O57*(1-(1+E$7)^-$B8)/E$7/(1+E$7)^DCF!O14+Assumptions!$C$21)/Assumptions!$C$12 -> 5.7819238 | F8: =(SUMPRODUCT('Scenario Engine'!F57:O57,1/(1+F$7)^DCF!F14:O14)+'Scenario Engine'!O57*(1-(1+F$7)^-$B8)/F$7/(1+F$7)^DCF!O14+Assumptions!$C$21)/Assumptions!$C$12 -> 5.5531848 | G8: =(SUMPRODUCT('Scenario Engine'!F57:O57,1/(1+G$7)^DCF!F14:O14)+'Scenario Engine'!O57*(1-(1+G$7)^-$B8)/G$7/(1+G$7)^DCF!O14+Assumptions!$C$21)/Assumptions!$C$12 -> 5.3377427
B9: 15 | C9: =(SUMPRODUCT('Scenario Engine'!F57:O57,1/(1+C$7)^DCF!F14:O14)+'Scenario Engine'!O57*(1-(1+C$7)^-$B9)/C$7/(1+C$7)^DCF!O14+Assumptions!$C$21)/Assumptions!$C$12 -> 7.031551 | D9: =(SUMPRODUCT('Scenario Engine'!F57:O57,1/(1+D$7)^DCF!F14:O14)+'Scenario Engine'!O57*(1-(1+D$7)^-$B9)/D$7/(1+D$7)^DCF!O14+Assumptions!$C$21)/Assumptions!$C$12 -> 6.6997128 | E9: =(SUMPRODUCT('Scenario Engine'!F57:O57,1/(1+E$7)^DCF!F14:O14)+'Scenario Engine'!O57*(1-(1+E$7)^-$B9)/E$7/(1+E$7)^DCF!O14+Assumptions!$C$21)/Assumptions!$C$12 -> 6.3907642 | F9: =(SUMPRODUCT('Scenario Engine'!F57:O57,1/(1+F$7)^DCF!F14:O14)+'Scenario Engine'!O57*(1-(1+F$7)^-$B9)/F$7/(1+F$7)^DCF!O14+Assumptions!$C$21)/Assumptions!$C$12 -> 6.1028261 | G9: =(SUMPRODUCT('Scenario Engine'!F57:O57,1/(1+G$7)^DCF!F14:O14)+'Scenario Engine'!O57*(1-(1+G$7)^-$B9)/G$7/(1+G$7)^DCF!O14+Assumptions!$C$21)/Assumptions!$C$12 -> 5.8341931
B10: 20 | C10: =(SUMPRODUCT('Scenario Engine'!F57:O57,1/(1+C$7)^DCF!F14:O14)+'Scenario Engine'!O57*(1-(1+C$7)^-$B10)/C$7/(1+C$7)^DCF!O14+Assumptions!$C$21)/Assumptions!$C$12 -> 7.5436067 | D10: =(SUMPRODUCT('Scenario Engine'!F57:O57,1/(1+D$7)^DCF!F14:O14)+'Scenario Engine'!O57*(1-(1+D$7)^-$B10)/D$7/(1+D$7)^DCF!O14+Assumptions!$C$21)/Assumptions!$C$12 -> 7.1509497 | E10: =(SUMPRODUCT('Scenario Engine'!F57:O57,1/(1+E$7)^DCF!F14:O14)+'Scenario Engine'!O57*(1-(1+E$7)^-$B10)/E$7/(1+E$7)^DCF!O14+Assumptions!$C$21)/Assumptions!$C$12 -> 6.7886541 | F10: =(SUMPRODUCT('Scenario Engine'!F57:O57,1/(1+F$7)^DCF!F14:O14)+'Scenario Engine'!O57*(1-(1+F$7)^-$B10)/F$7/(1+F$7)^DCF!O14+Assumptions!$C$21)/Assumptions!$C$12 -> 6.4538929 | G10: =(SUMPRODUCT('Scenario Engine'!F57:O57,1/(1+G$7)^DCF!F14:O14)+'Scenario Engine'!O57*(1-(1+G$7)^-$B10)/G$7/(1+G$7)^DCF!O14+Assumptions!$C$21)/Assumptions!$C$12 -> 6.1441366
B11: 25 | C11: =(SUMPRODUCT('Scenario Engine'!F57:O57,1/(1+C$7)^DCF!F14:O14)+'Scenario Engine'!O57*(1-(1+C$7)^-$B11)/C$7/(1+C$7)^DCF!O14+Assumptions!$C$21)/Assumptions!$C$12 -> 7.8940457 | D11: =(SUMPRODUCT('Scenario Engine'!F57:O57,1/(1+D$7)^DCF!F14:O14)+'Scenario Engine'!O57*(1-(1+D$7)^-$B11)/D$7/(1+D$7)^DCF!O14+Assumptions!$C$21)/Assumptions!$C$12 -> 7.4527077 | E11: =(SUMPRODUCT('Scenario Engine'!F57:O57,1/(1+E$7)^DCF!F14:O14)+'Scenario Engine'!O57*(1-(1+E$7)^-$B11)/E$7/(1+E$7)^DCF!O14+Assumptions!$C$21)/Assumptions!$C$12 -> 7.0486835 | F11: =(SUMPRODUCT('Scenario Engine'!F57:O57,1/(1+F$7)^DCF!F14:O14)+'Scenario Engine'!O57*(1-(1+F$7)^-$B11)/F$7/(1+F$7)^DCF!O14+Assumptions!$C$21)/Assumptions!$C$12 -> 6.6781262 | G11: =(SUMPRODUCT('Scenario Engine'!F57:O57,1/(1+G$7)^DCF!F14:O14)+'Scenario Engine'!O57*(1-(1+G$7)^-$B11)/G$7/(1+G$7)^DCF!O14+Assumptions!$C$21)/Assumptions!$C$12 -> 6.3376403
B12: 30 | C12: =(SUMPRODUCT('Scenario Engine'!F57:O57,1/(1+C$7)^DCF!F14:O14)+'Scenario Engine'!O57*(1-(1+C$7)^-$B12)/C$7/(1+C$7)^DCF!O14+Assumptions!$C$21)/Assumptions!$C$12 -> 8.1338781 | D12: =(SUMPRODUCT('Scenario Engine'!F57:O57,1/(1+D$7)^DCF!F14:O14)+'Scenario Engine'!O57*(1-(1+D$7)^-$B12)/D$7/(1+D$7)^DCF!O14+Assumptions!$C$21)/Assumptions!$C$12 -> 7.6545039 | E12: =(SUMPRODUCT('Scenario Engine'!F57:O57,1/(1+E$7)^DCF!F14:O14)+'Scenario Engine'!O57*(1-(1+E$7)^-$B12)/E$7/(1+E$7)^DCF!O14+Assumptions!$C$21)/Assumptions!$C$12 -> 7.2186181 | F12: =(SUMPRODUCT('Scenario Engine'!F57:O57,1/(1+F$7)^DCF!F14:O14)+'Scenario Engine'!O57*(1-(1+F$7)^-$B12)/F$7/(1+F$7)^DCF!O14+Assumptions!$C$21)/Assumptions!$C$12 -> 6.8213485 | G12: =(SUMPRODUCT('Scenario Engine'!F57:O57,1/(1+G$7)^DCF!F14:O14)+'Scenario Engine'!O57*(1-(1+G$7)^-$B12)/G$7/(1+G$7)^DCF!O14+Assumptions!$C$21)/Assumptions!$C$12 -> 6.4584483
B14: Base case sits at WACC 8.88% and a terminal life derived from the remaining ore base (highlighted).
B16: 2. Linear price and cost sensitivity coefficients
B17: Base case, per forecast year | C17: FY24A | D17: FY25A | E17: FY26A | F17: FY27F | G17: FY28F | H17: FY29F | I17: FY30F | J17: FY31F | K17: FY32F | L17: FY33F | M17: FY34F | N17: FY35F | O17: FY36F
B18: Concentrate sold (kt) | F18: ='Scenario Engine'!F42 -> 1065 | G18: ='Scenario Engine'!G42 -> 1115 | H18: ='Scenario Engine'!H42 -> 1115 | I18: ='Scenario Engine'!I42 -> 1365 | J18: ='Scenario Engine'!J42 -> 1665 | K18: ='Scenario Engine'!K42 -> 2065 | L18: ='Scenario Engine'!L42 -> 2350 | M18: ='Scenario Engine'!M42 -> 2460 | ... O18: ='Scenario Engine'!O42 -> 2500
B19: Realised price (A$/t) | F19: ='Scenario Engine'!F44 -> 2575.7576 | G19: ='Scenario Engine'!G44 -> 2656.7164 | H19: ='Scenario Engine'!H44 -> 2720.5882 | I19: ='Scenario Engine'!I44 -> 2608.6957 | J19: ='Scenario Engine'!J44 -> 2500 | K19: ='Scenario Engine'!K44 -> 2500 | L19: ='Scenario Engine'!L44 -> 2500 | M19: ='Scenario Engine'!M44 -> 2500 | ... O19: ='Scenario Engine'!O44 -> 2500
